<!DOCTYPE html>
<html lang="en">
<head>
    <meta charset="UTF-8">
    <title>promise的几个关键问题6</title>
</head>
<body>
    <!--
        promise错误穿透
          1.在使用promise then方法的链式调用时，可以在最后用catch指定一个失败的回调
          2.前面的操作出了错误，都会传到失败的回调中处理
          注意：如果不存在then的链式调用，就不需要考虑then的错误穿透
    -->
    <script>
        function sendAjax(url,data,method = 'GET') {
            return new Promise((resolve, reject) => {
                const xhr = new XMLHttpRequest();
                xhr.onreadystatechange = () => {
                    if (xhr.readyState === 4){
                        if(xhr.status >= 200 && xhr.status <= 300) {
                            resolve(xhr.response)
                        }else {
                            reject('error出错了')
                        }
                    }
                };
                let str = '';
                for (const key in data) {
                    str += `${key}=${data[key]}&`
                }
                str = str.slice(0,-1)
                xhr.open(method ,url + '?' +str);
                // xhr.responseType = 'json'
                xhr.send();
            })
        }
        //
        // sendAjax('https://api.uixsj.cn/hitokoto/get',{type:'social'}).then(value => {
        //     console.log('第一次请求成功', value)
        //     return sendAjax('https://api.uixsj.cn/hitokoto/get2',{type:'social'})
        //         },
        //         err => {
        //             console.log('第一次请求失败', err)
        //             return new Promise(()=>{})
        //         })
        //     .then(value => {
        //         console.log('第二次请求成功', value)
        //         return sendAjax('https://api.uixsj.cn/hitokoto/get',{type:'social'})
        //         },
        //         reason => {
        //             console.log('第二次请求失败', reason)
        //             return new Promise(()=>{})
        //         })
        //     .then(value => {
        //         console.log('第三次请求成功', value)
        //     }
        //     ,reason => {
        //         console.log('第三次请求失败', reason)
        //         return new Promise(()=>{})
        //     }).catch(reason =>{
        //         console.log('catch', reason)
        //     })

        //演示错误的穿透
        const p = new Promise((resolve, reject) => {
            setTimeout(()=>{
                // resolve(1)
                reject(-1)
            },1000)
        })
        //then方法链式调用时，不用指定失败的回调，在最后定义catch方法就可以捕获到错误信息
        //相当于在每一个then方法中加了一条语句： reason => {throw reason}
        p.then(
            value => {console.log('成功了1',value);return 'b'},
        ).then(
            value => {console.log('成功了2',value);return Promise.reject(-108)},
        ).catch(
            reason => {console.log('失败了',reason);return -2}
        )
    </script>
</body>
</html>
